Workbook
Name Slicer_Machine_ID: #N/A
Name Slicer_Month: #N/A
Name Slicer_Product_Type: #N/A
Name Slicer_Production_Line: #N/A
Name Slicer_Shift: #N/A

Sheet Sheet13
A3: Row Labels | B3: Sum of Scrap_Cost
A4: Line 1 | B4: 50339.315
A5: Line 2 | B5: 62030.729
A6: Line 3 | B6: 78358.048
A7: Line 4 | B7: 47228.223
A8: Line 5 | B8: 63087.38
A9: Grand Total | B9: 301043.7

Sheet 01_Manufacturing_Data
A1: Record_ID | B1: Production_Date | C1: Month | D1: Plant | E1: Production_Line | F1: Machine_ID | G1: Shift | H1: Product_Type | I1: Batch_ID | J1: Operator_ID | K1: Planned_Quantity | L1: Produced_Quantity | M1: Good_Quantity | N1: Defect_Quantity | O1: Scrap_Quantity | P1: Downtime_Minutes | Q1: Downtime_Reason | R1: Ideal_Cycle_Time_Sec | S1: Actual_Cycle_Time_Sec | T1: Machine_Temperature_C | U1: Machine_Vibration_mm_s | V1: Energy_Consumption_kWh | W1: Raw_Material_Cost | X1: Labour_Hours | Y1: Maintenance_Status | Z1: Maintenance_Days_Ago | AA1: Revenue | AB1: Quality_Score | AC1: Production_Cost | AD1: Scrap_Cost | AE1: Planned_Production_Time_Min | AF1: Availability | AG1: Profit | AH1: Production_Achievement_% | AI1: Defect_Rate_% | AJ1: Scrap_Rate_% | AK1: Good_Rate_% | AL1: Downtime_Hours | AM1: Operating_Time_Min | AN1: Actual_Production_Rate | AO1: Ideal_Production_Rate | AP1: Performance_% | AQ1: Quality_% | AR1: OEE_% | AS1: Cost_Per_Unit | AT1: Profit_Per_Unit | AU1: Maintenance_Risk | AV1: Anomaly_Flag
A2: 1 | B2: 46186 | C2: =TEXT(B2,"mmmm") -> June | D2: Plant A | E2: Line 1 | F2: M103 | G2: Morning | H2: Product A | I2: B260613-0001 | J2: OP107 | K2: 764 | L2: 737 | M2: 705 | N2: 32 | O2: 8 | P2: 22 | Q2: Machine Breakdown | R2: 42 | S2: 44 | T2: 69 | U2: 1.91 | V2: 30.4 | W2: 13077.65 | X2: 8.29 | Y2: Completed | Z2: 29 | AA2: 22174.65 | AB2: 0.95658073 | AC2: 17081.75 | AD2: 141.9555 | AE2: 534.8 | AF2: 0.95886313 | AG2: 4950.9445 | AH2: =IFERROR(L2/K2,0) -> 0.96465969 | AI2: =IFERROR(N2/L2,0) -> 0.043419267 | AJ2: =IFERROR(O2/L2,0) -> 0.010854817 | AK2: =IFERROR(M2/L2,0) -> 0.95658073 | AL2: =P2/60 -> 0.36666667 | AM2: =MAX(0,AE2-P2) -> 512.8 | AN2: =IFERROR(L2/AM2,0) -> 1.4372075 | AO2: =IFERROR(60/R2,0) -> 1.4285714 | AP2: =IFERROR(AN2/AO2,0) -> 1.0060452 | AQ2: =IFERROR(M2/L2,0) -> 0.95658073 | AR2: =AF2*AP2*AQ2 -> 0.92277487 | AS2: =IFERROR(AC2/L2,0) -> 23.177408 | AT2: =IFERROR(AG2/L2,0) -> 6.7176995 | AU2: =IF(OR(Y2="Overdue",P2>=120,T2>=85,U2>=4,AI2>=0.12,AR2<0.8),"High",IF(OR(Y2="Pending",Z2>=30,P2>=60,T2>=80,U2>=3,AI2>=0.08,AR2<0.85),"Medium","Low")) -> Low | AV2: =IF(OR(P2>=120,T2>=90,U2>=4.5,AI2>=0.15,AR2<0.75),"Critical",IF(OR(P2>=60,T2>=80,U2>=3,AI2>=0.08,AR2<0.85),"Warning","Normal")) -> Normal
A3: 2 | B3: 46109 | C3: =TEXT(B3,"mmmm") -> March | D3: Plant A | E3: Line 1 | F3: M102 | G3: Morning | H3: Product D | I3: B260328-0002 | J3: OP117 | K3: 702 | L3: 740 | M3: 698 | N3: 42 | O3: 16 | P3: 0 | Q3: No Downtime | R3: 45 | S3: 46 | T3: 63.1 | U3: 1.8 | V3: 26.27 | W3: 14343.22 | X3: 8.38 | Y3: Completed | Z3: 12 | AA3: 23814.06 | AB3: 0.94324324 | AC3: 18350.65 | AD3: 310.12368 | AE3: 526.5 | AF3: 1 | AG3: 5153.2863 | AH3: =IFERROR(L3/K3,0) -> 1.0541311 | AI3: =IFERROR(N3/L3,0) -> 0.056756757 | AJ3: =IFERROR(O3/L3,0) -> 0.021621622 | AK3: =IFERROR(M3/L3,0) -> 0.94324324 | AL3: =P3/60 -> 0 | AM3: =MAX(0,AE3-P3) -> 526.5 | AN3: =IFERROR(L3/AM3,0) -> 1.4055081 | AO3: =IFERROR(60/R3,0) -> 1.3333333 | AP3: =IFERROR(AN3/AO3,0) -> 1.0541311 | AQ3: =IFERROR(M3/L3,0) -> 0.94324324 | AR3: =AF3*AP3*AQ3 -> 0.99430199 | AS3: =IFERROR(AC3/L3,0) -> 24.798176 | AT3: =IFERROR(AG3/L3,0) -> 6.9639004 | AU3: =IF(OR(Y3="Overdue",P3>=120,T3>=85,U3>=4,AI3>=0.12,AR3<0.8),"High",IF(OR(Y3="Pending",Z3>=30,P3>=60,T3>=80,U3>=3,AI3>=0.08,AR3<0.85),"Medium","Low")) -> Low | AV3: =IF(OR(P3>=120,T3>=90,U3>=4.5,AI3>=0.15,AR3<0.75),"Critical",IF(OR(P3>=60,T3>=80,U3>=3,AI3>=0.08,AR3<0.85),"Warning","Normal")) -> Normal
A4: 3 | B4: 46082 | C4: =TEXT(B4,"mmmm") -> March | D4: Plant A | E4: Line 4 | F4: M402 | G4: Evening | H4: Product D | I4: B260301-0003 | J4: OP111 | K4: 869 | L4: 910 | M4: 870 | N4: 40 | O4: 10 | P4: 0 | Q4: No Downtime | R4: 45 | S4: 48 | T4: 75.1 | U4: 1.72 | V4: 36.43 | W4: 18027.33 | X4: 8.66 | Y4: Scheduled | Z4: 15 | AA4: 29638.7 | AB4: 0.95604396 | AC4: 22252.2 | AD4: 198.10253 | AE4: 651.75 | AF4: 1 | AG4: 7188.3975 | AH4: =IFERROR(L4/K4,0) -> 1.0471807 | AI4: =IFERROR(N4/L4,0) -> 0.043956044 | AJ4: =IFERROR(O4/L4,0) -> 0.010989011 | AK4: =IFERROR(M4/L4,0) -> 0.95604396 | AL4: =P4/60 -> 0 | AM4: =MAX(0,AE4-P4) -> 651.75 | AN4: =IFERROR(L4/AM4,0) -> 1.3962409 | AO4: =IFERROR(60/R4,0) -> 1.3333333 | AP4: =IFERROR(AN4/AO4,0) -> 1.0471807 | AQ4: =IFERROR(M4/L4,0) -> 0.95604396 | AR4: =AF4*AP4*AQ4 -> 1.0011507 | AS4: =IFERROR(AC4/L4,0) -> 24.452967 | AT4: =IFERROR(AG4/L4,0) -> 7.8993379 | AU4: =IF(OR(Y4="Overdue",P4>=120,T4>=85,U4>=4,AI4>=0.12,AR4<0.8),"High",IF(OR(Y4="Pending",Z4>=30,P4>=60,T4>=80,U4>=3,AI4>=0.08,AR4<0.85),"Medium","Low")) -> Low | AV4: =IF(OR(P4>=120,T4>=90,U4>=4.5,AI4>=0.15,AR4<0.75),"Critical",IF(OR(P4>=60,T4>=80,U4>=3,AI4>=0.08,AR4<0.85),"Warning","Normal")) -> Normal
A5: 4 | B5: 46031 | C5: =TEXT(B5,"mmmm") -> January | D5: Plant B | E5: Line 4 | F5: M402 | G5: Morning | H5: Product E | I5: B260109-0004 | J5: OP121 | K5: 504 | L5: 591 | M5: 559 | N5: 32 | O5: 8 | P5: 0 | Q5: No Downtime | R5: 64 | S5: 66 | T5: 71.6 | U5: 2.39 | V5: 21.04 | W5: 18099.83 | X5: 9.29 | Y5: Overdue | Z5: 22 | AA5: 29084.61 | AB5: 0.94585448 | AC5: 22469.69 | AD5: 245.00616 | AE5: 537.6 | AF5: 1 | AG5: 6369.9138 | AH5: =IFERROR(L5/K5,0) -> 1.172619 | AI5: =IFERROR(N5/L5,0) -> 0.054145516 | AJ5: =IFERROR(O5/L5,0) -> 0.013536379 | AK5: =IFERROR(M5/L5,0) -> 0.94585448 | AL5: =P5/60 -> 0 | AM5: =MAX(0,AE5-P5) -> 537.6 | AN5: =IFERROR(L5/AM5,0) -> 1.0993304 | AO5: =IFERROR(60/R5,0) -> 0.9375 | AP5: =IFERROR(AN5/AO5,0) -> 1.172619 | AQ5: =IFERROR(M5/L5,0) -> 0.94585448 | AR5: =AF5*AP5*AQ5 -> 1.109127 | AS5: =IFERROR(AC5/L5,0) -> 38.01978 | AT5: =IFERROR(AG5/L5,0) -> 10.778196 | AU5: =IF(OR(Y5="Overdue",P5>=120,T5>=85,U5>=4,AI5>=0.12,AR5<0.8),"High",IF(OR(Y5="Pending",Z5>=30,P5>=60,T5>=80,U5>=3,AI5>=0.08,AR5<0.85),"Medium","Low")) -> High | AV5: =IF(OR(P5>=120,T5>=90,U5>=4.5,AI5>=0.15,AR5<0.75),"Critical",IF(OR(P5>=60,T5>=80,U5>=3,AI5>=0.08,AR5<0.85),"Warning","Normal")) -> Normal
A6: 5 | B6: 46046 | C6: =TEXT(B6,"mmmm") -> January | D6: Plant A | E6: Line 1 | F6: M101 | G6: Evening | H6: Product D | I6: B260124-0005 | J6: OP128 | K6: 712 | L6: 728 | M6: 699 | N6: 29 | O6: 11 | P6: 9 | Q6: Material Shortage | R6: 45 | S6: 47 | T6: 69.3 | U6: 2.74 | V6: 24.02 | W6: 14311.8 | X6: 7.37 | Y6: Scheduled | Z6: 12 | AA6: 24787.47 | AB6: 0.96016484 | AC6: 17844.48 | AD6: 216.24973 | AE6: 534 | AF6: 0.98314607 | AG6: 6726.7403 | AH6: =IFERROR(L6/K6,0) -> 1.0224719 | AI6: =IFERROR(N6/L6,0) -> 0.039835165 | AJ6: =IFERROR(O6/L6,0) -> 0.01510989 | AK6: =IFERROR(M6/L6,0) -> 0.96016484 | AL6: =P6/60 -> 0.15 | AM6: =MAX(0,AE6-P6) -> 525 | AN6: =IFERROR(L6/AM6,0) -> 1.3866667 | AO6: =IFERROR(60/R6,0) -> 1.3333333 | AP6: =IFERROR(AN6/AO6,0) -> 1.04 | AQ6: =IFERROR(M6/L6,0) -> 0.96016484 | AR6: =AF6*AP6*AQ6 -> 0.98174157 | AS6: =IFERROR(AC6/L6,0) -> 24.511648 | AT6: =IFERROR(AG6/L6,0) -> 9.2400278 | AU6: =IF(OR(Y6="Overdue",P6>=120,T6>=85,U6>=4,AI6>=0.12,AR6<0.8),"High",IF(OR(Y6="Pending",Z6>=30,P6>=60,T6>=80,U6>=3,AI6>=0.08,AR6<0.85),"Medium","Low")) -> Low | AV6: =IF(OR(P6>=120,T6>=90,U6>=4.5,AI6>=0.15,AR6<0.75),"Critical",IF(OR(P6>=60,T6>=80,U6>=3,AI6>=0.08,AR6<0.85),"Warning","Normal")) -> Normal
A7: 6 | B7: 46151 | C7: =TEXT(B7,"mmmm") -> May | D7: Plant A | E7: Line 5 | F7: M501 | G7: Night | H7: Product B | I7: B260509-0006 | J7: OP133 | K7: 721 | L7: 542 | M7: 508 | N7: 34 | O7: 14 | P7: 31 | Q7: Operator Issue | R7: 49 | S7: 52 | T7: 76.4 | U7: 2.09 | V7: 23.48 | W7: 11648.58 | X7: 5.56 | Y7: Overdue | Z7: 40 | AA7: 19821.67 | AB7: 0.93726937 | AC7: 14361.9 | AD7: 300.88583 | AE7: 588.81667 | AF7: 0.94735203 | AG7: 5158.8842 | AH7: =IFERROR(L7/K7,0) -> 0.7517337 | AI7: =IFERROR(N7/L7,0) -> 0.062730627 | AJ7: =IFERROR(O7/L7,0) -> 0.025830258 | AK7: =IFERROR(M7/L7,0) -> 0.93726937 | AL7: =P7/60 -> 0.51666667 | AM7: =MAX(0,AE7-P7) -> 557.81667 | AN7: =IFERROR(L7/AM7,0) -> 0.9716454 | AO7: =IFERROR(60/R7,0) -> 1.2244898 | AP7: =IFERROR(AN7/AO7,0) -> 0.79351041 | AQ7: =IFERROR(M7/L7,0) -> 0.93726937 | AR7: =AF7*AP7*AQ7 -> 0.70457698 | AS7: =IFERROR(AC7/L7,0) -> 26.49797 | AT7: =IFERROR(AG7/L7,0) -> 9.5182365 | AU7: =IF(OR(Y7="Overdue",P7>=120,T7>=85,U7>=4,AI7>=0.12,AR7<0.8),"High",IF(OR(Y7="Pending",Z7>=30,P7>=60,T7>=80,U7>=3,AI7>=0.08,AR7<0.85),"Medium","Low")) -> High | AV7: =IF(OR(P7>=120,T7>=90,U7>=4.5,AI7>=0.15,AR7<0.75),"Critical",IF(OR(P7>=60,T7>=80,U7>=3,AI7>=0.08,AR7<0.85),"Warning","Normal")) -> Critical
A8: 7 | B8: 46044 | C8: =TEXT(B8,"mmmm") -> January | D8: Plant B | E8: Line 1 | F8: M103 | G8: Evening | H8: Product A | I8: B260122-0007 | J8: OP131 | K8: 804 | L8: 758 | M8: 722 | N8: 36 | O8: 10 | P8: 10 | Q8: Machine Breakdown | R8: 42 | S8: 43 | T8: 68.7 | U8: 1.5 | V8: 26.72 | W8: 13559.73 | X8: 7.84 | Y8: Scheduled | Z8: 32 | AA8: 22729.87 | AB8: 0.9525066 | AC8: 17328.21 | AD8: 178.88826 | AE8: 562.8 | AF8: 0.9822317 | AG8: 5222.7717 | AH8: =IFERROR(L8/K8,0) -> 0.94278607 | AI8: =IFERROR(N8/L8,0) -> 0.047493404 | AJ8: =IFERROR(O8/L8,0) -> 0.013192612 | AK8: =IFERROR(M8/L8,0) -> 0.9525066 | AL8: =P8/60 -> 0.16666667 | AM8: =MAX(0,AE8-P8) -> 552.8 | AN8: =IFERROR(L8/AM8,0) -> 1.3712012 | AO8: =IFERROR(60/R8,0) -> 1.4285714 | AP8: =IFERROR(AN8/AO8,0) -> 0.95984081 | AQ8: =IFERROR(M8/L8,0) -> 0.9525066 | AR8: =AF8*AP8*AQ8 -> 0.89800995 | AS8: =IFERROR(AC8/L8,0) -> 22.860435 | AT8: =IFERROR(AG8/L8,0) -> 6.8902002 | AU8: =IF(OR(Y8="Overdue",P8>=120,T8>=85,U8>=4,AI8>=0.12,AR8<0.8),"High",IF(OR(Y8="Pending",Z8>=30,P8>=60,T8>=80,U8>=3,AI8>=0.08,AR8<0.85),"Medium","Low")) -> Medium | AV8: =IF(OR(P8>=120,T8>=90,U8>=4.5,AI8>=0.15,AR8<0.75),"Critical",IF(OR(P8>=60,T8>=80,U8>=3,AI8>=0.08,AR8<0.85),"Warning","Normal")) -> Normal
A9: 8 | B9: 46079 | C9: =TEXT(B9,"mmmm") -> February | D9: Plant A | E9: Line 1 | F9: M103 | G9: Evening | H9: Product A | I9: B260226-0008 | J9: OP103 | K9: 889 | L9: 806 | M9: 750 | N9: 56 | O9: 13 | P9: 43 | Q9: Machine Breakdown | R9: 42 | S9: 41 | T9: 82.3 | U9: 2.75 | V9: 25.83 | W9: 14774.26 | X9: 7.93 | Y9: Overdue | Z9: 60 | AA9: 24249.64 | AB9: 0.93052109 | AC9: 18575.23 | AD9: 238.29452 | AE9: 622.3 | AF9: 0.93090149 | AG9: 5436.1155 | AH9: =IFERROR(L9/K9,0) -> 0.90663667 | AI9: =IFERROR(N9/L9,0) -> 0.069478908 | AJ9: =IFERROR(O9/L9,0) -> 0.016129032 | AK9: =IFERROR(M9/L9,0) -> 0.93052109 | AL9: =P9/60 -> 0.71666667 | AM9: =MAX(0,AE9-P9) -> 579.3 | AN9: =IFERROR(L9/AM9,0) -> 1.3913344 | AO9: =IFERROR(60/R9,0) -> 1.4285714 | AP9: =IFERROR(AN9/AO9,0) -> 0.97393406 | AQ9: =IFERROR(M9/L9,0) -> 0.93052109 | AR9: =AF9*AP9*AQ9 -> 0.84364454 | AS9: =IFERROR(AC9/L9,0) -> 23.046191 | AT9: =IFERROR(AG9/L9,0) -> 6.7445602 | AU9: =IF(OR(Y9="Overdue",P9>=120,T9>=85,U9>=4,AI9>=0.12,AR9<0.8),"High",IF(OR(Y9="Pending",Z9>=30,P9>=60,T9>=80,U9>=3,AI9>=0.08,AR9<0.85),"Medium","Low")) -> High | AV9: =IF(OR(P9>=120,T9>=90,U9>=4.5,AI9>=0.15,AR9<0.75),"Critical",IF(OR(P9>=60,T9>=80,U9>=3,AI9>=0.08,AR9<0.85),"Warning","Normal")) -> Warning
A10: 9 | B10: 46188 | C10: =TEXT(B10,"mmmm") -> June | D10: Plant A | E10: Line 1 | F10: M102 | G10: Evening | H10: Product D | I10: B260615-0009 | J10: OP107 | K10: 807 | L10: 749 | M10: 714 | N10: 35 | O10: 12 | P10: 19 | Q10: Machine Breakdown | R10: 45 | S10: 46 | T10: 70.6 | U10: 2.39 | V10: 26.91 | W10: 14605.07 | X10: 8.99 | Y10: Completed | Z10: 17 | AA10: 24849.68 | AB10: 0.95327103 | AC10: 18892.76 | AD10: 233.99311 | AE10: 605.25 | AF10: 0.96860801 | AG10: 5722.9269 | AH10: =IFERROR(L10/K10,0) -> 0.92812887 | AI10: =IFERROR(N10/L10,0) -> 0.046728972 | AJ10: =IFERROR(O10/L10,0) -> 0.016021362 | AK10: =IFERROR(M10/L10,0) -> 0.95327103 | AL10: =P10/60 -> 0.31666667 | AM10: =MAX(0,AE10-P10) -> 586.25 | AN10: =IFERROR(L10/AM10,0) -> 1.2776119 | AO10: =IFERROR(60/R10,0) -> 1.3333333 | AP10: =IFERROR(AN10/AO10,0) -> 0.95820896 | AQ10: =IFERROR(M10/L10,0) -> 0.95327103 | AR10: =AF10*AP10*AQ10 -> 0.88475836 | AS10: =IFERROR(AC10/L10,0) -> 25.223979 | AT10: =IFERROR(AG10/L10,0) -> 7.6407569 | AU10: =IF(OR(Y10="Overdue",P10>=120,T10>=85,U10>=4,AI10>=0.12,AR10<0.8),"High",IF(OR(Y10="Pending",Z10>=30,P10>=60,T10>=80,U10>=3,AI10>=0.08,AR10<0.85),"Medium","Low")) -> Low | AV10: =IF(OR(P10>=120,T10>=90,U10>=4.5,AI10>=0.15,AR10<0.75),"Critical",IF(OR(P10>=60,T10>=80,U10>=3,AI10>=0.08,AR10<0.85),"Warning","Normal")) -> Normal
A11: 10 | B11: 46146 | C11: =TEXT(B11,"mmmm") -> May | D11: Plant A | E11: Line 4 | F11: M401 | G11: Morning | H11: Product A | I11: B260504-0010 | J11: OP125 | K11: 855 | L11: 925 | M11: 893 | N11: 32 | O11: 7 | P11: 22 | Q11: Quality Inspection | R11: 42 | S11: 45 | T11: 73.5 | U11: 1.39 | V11: 29.34 | W11: 17596.59 | X11: 8.01 | Y11: Completed | Z11: 1 | AA11: 27804.69 | AB11: 0.96540541 | AC11: 21465.15 | AD11: 133.16338 | AE11: 598.5 | AF11: 0.96324144 | AG11: 6206.3766 | AH11: =IFERROR(L11/K11,0) -> 1.0818713 | AI11: =IFERROR(N11/L11,0) -> 0.034594595 | AJ11: =IFERROR(O11/L11,0) -> 0.0075675676 | AK11: =IFERROR(M11/L11,0) -> 0.96540541 | AL11: =P11/60 -> 0.36666667 | AM11: =MAX(0,AE11-P11) -> 576.5 | AN11: =IFERROR(L11/AM11,0) -> 1.60451 | AO11: =IFERROR(60/R11,0) -> 1.4285714 | AP11: =IFERROR(AN11/AO11,0) -> 1.123157 | AQ11: =IFERROR(M11/L11,0) -> 0.96540541 | AR11: =AF11*AP11*AQ11 -> 1.0444444 | AS11: =IFERROR(AC11/L11,0) -> 23.205568 | AT11: =IFERROR(AG11/L11,0) -> 6.7095963 | AU11: =IF(OR(Y11="Overdue",P11>=120,T11>=85,U11>=4,AI11>=0.12,AR11<0.8),"High",IF(OR(Y11="Pending",Z11>=30,P11>=60,T11>=80,U11>=3,AI11>=0.08,AR11<0.85),"Medium","Low")) -> Low | AV11: =IF(OR(P11>=120,T11>=90,U11>=4.5,AI11>=0.15,AR11<0.75),"Critical",IF(OR(P11>=60,T11>=80,U11>=3,AI11>=0.08,AR11<0.85),"Warning","Normal")) -> Normal
A12: 11 | B12: 46145 | C12: =TEXT(B12,"mmmm") -> May | D12: Plant A | E12: Line 1 | F12: M103 | G12: Morning | H12: Product A | I12: B260503-0011 | J12: OP105 | K12: 840 | L12: 871 | M12: 836 | N12: 35 | O12: 12 | P12: 18 | Q12: Tool Change | R12: 42 | S12: 41 | T12: 75.6 | U12: 1.69 | V12: 28.77 | W12: 15399.76 | X12: 9.67 | Y12: Scheduled | Z12: 38 | AA12: 27440.63 | AB12: 0.9598163 | AC12: 20010.19 | AD12: 212.16661 | AE12: 588 | AF12: 0.96938776 | AG12: 7218.2734 | AH12: =IFERROR(L12/K12,0) -> 1.0369048 | AI12: =IFERROR(N12/L12,0) -> 0.040183697 | AJ12: =IFERROR(O12/L12,0) -> 0.013777268 | AK12: =IFERROR(M12/L12,0) -> 0.9598163 | AL12: =P12/60 -> 0.3 | AM12: =MAX(0,AE12-P12) -> 570 | AN12: =IFERROR(L12/AM12,0) -> 1.5280702 | AO12: =IFERROR(60/R12,0) -> 1.4285714 | AP12: =IFERROR(AN12/AO12,0) -> 1.0696491 | AQ12: =IFERROR(M12/L12,0) -> 0.9598163 | AR12: =AF12*AP12*AQ12 -> 0.9952381 | AS12: =IFERROR(AC12/L12,0) -> 22.973812 | AT12: =IFERROR(AG12/L12,0) -> 8.2873403 | AU12: =IF(OR(Y12="Overdue",P12>=120,T12>=85,U12>=4,AI12>=0.12,AR12<0.8),"High",IF(OR(Y12="Pending",Z12>=30,P12>=60,T12>=80,U12>=3,AI12>=0.08,AR12<0.85),"Medium","Low")) -> Medium | AV12: =IF(OR(P12>=120,T12>=90,U12>=4.5,AI12>=0.15,AR12<0.75),"Critical",IF(OR(P12>=60,T12>=80,U12>=3,AI12>=0.08,AR12<0.85),"Warning","Normal")) -> Normal
A13: 12 | B13: 46041 | C13: =TEXT(B13,"mmmm") -> January | D13: Plant A | E13: Line 4 | F13: M403 | G13: Night | H13: Product E | I13: B260119-0012 | J13: OP105 | K13: 587 | L13: 578 | M13: 534 | N13: 44 | O13: 15 | P13: 18 | Q13: Setup Time | R13: 64 | S13: 71 | T13: 70 | U13: 2.26 | V13: 22.12 | W13: 18249.07 | X13: 7.12 | Y13: Scheduled | Z13: 19 | AA13: 27433.75 | AB13: 0.92387543 | AC13: 21652.15 | AD13: 473.59178 | AE13: 626.13333 | AF13: 0.97125213 | AG13: 5308.0082 | AH13: =IFERROR(L13/K13,0) -> 0.9846678 | AI13: =IFERROR(N13/L13,0) -> 0.076124567 | AJ13: =IFERROR(O13/L13,0) -> 0.025951557 | AK13: =IFERROR(M13/L13,0) -> 0.92387543 | AL13: =P13/60 -> 0.3 | AM13: =MAX(0,AE13-P13) -> 608.13333 | AN13: =IFERROR(L13/AM13,0) -> 0.95044946 | AO13: =IFERROR(60/R13,0) -> 0.9375 | AP13: =IFERROR(AN13/AO13,0) -> 1.0138128 | AQ13: =IFERROR(M13/L13,0) -> 0.92387543 | AR13: =AF13*AP13*AQ13 -> 0.90971039 | AS13: =IFERROR(AC13/L13,0) -> 37.460467 | AT13: =IFERROR(AG13/L13,0) -> 9.1834052 | AU13: =IF(OR(Y13="Overdue",P13>=120,T13>=85,U13>=4,AI13>=0.12,AR13<0.8),"High",IF(OR(Y13="Pending",Z13>=30,P13>=60,T13>=80,U13>=3,AI13>=0.08,AR13<0.85),"Medium","Low")) -> Low | AV13: =IF(OR(P13>=120,T13>=90,U13>=4.5,AI13>=0.15,AR13<0.75),"Critical",IF(OR(P13>=60,T13>=80,U13>=3,AI13>=0.08,AR13<0.85),"Warning","Normal")) -> Normal
... A1001: 1000 | B1001: 46132 | C1001: =TEXT(B1001,"mmmm") -> April | D1001: Plant A | E1001: Line 2 | F1001: M202 | G1001: Night | H1001: Product C | I1001: B260420-1000 | J1001: OP124 | K1001: 732 | L1001: 628 | M1001: 596 | N1001: 32 | O1001: 9 | P1001: 13 | Q1001: Material Shortage | R1001: 57 | S1001: 64 | T1001: 60.3 | U1001: 1.49 | V1001: 26.07 | W1001: 16530.14 | X1001: 8.08 | Y1001: Overdue | Z1001: 25 | AA1001: 27853.42 | AB1001: 0.94904459 | AC1001: 20400.77 | AD1001: 236.89691 | AE1001: 695.4 | AF1001: 0.98130572 | AG1001: 7215.7531 | AH1001: =IFERROR(L1001/K1001,0) -> 0.8579235 | AI1001: =IFERROR(N1001/L1001,0) -> 0.050955414 | AJ1001: =IFERROR(O1001/L1001,0) -> 0.01433121 | AK1001: =IFERROR(M1001/L1001,0) -> 0.94904459 | AL1001: =P1001/60 -> 0.21666667 | AM1001: =MAX(0,AE1001-P1001) -> 682.4 | AN1001: =IFERROR(L1001/AM1001,0) -> 0.92028136 | AO1001: =IFERROR(60/R1001,0) -> 1.0526316 | AP1001: =IFERROR(AN1001/AO1001,0) -> 0.87426729 | AQ1001: =IFERROR(M1001/L1001,0) -> 0.94904459 | AR1001: =AF1001*AP1001*AQ1001 -> 0.81420765 | AS1001: =IFERROR(AC1001/L1001,0) -> 32.485303 | AT1001: =IFERROR(AG1001/L1001,0) -> 11.490053 | AU1001: =IF(OR(Y1001="Overdue",P1001>=120,T1001>=85,U1001>=4,AI1001>=0.12,AR1001<0.8),"High",IF(OR(Y1001="Pending",Z1001>=30,P1001>=60,T1001>=80,U1001>=3,AI1001>=0.08,AR1001<0.85),"Medium","Low")) -> High | AV1001: =IF(OR(P1001>=120,T1001>=90,U1001>=4.5,AI1001>=0.15,AR1001<0.75),"Critical",IF(OR(P1001>=60,T1001>=80,U1001>=3,AI1001>=0.08,AR1001<0.85),"Warning","Normal")) -> Warning

Sheet 02_Data_Dictionary
A1: DATA DICTIONARY
A2: Column | B2: Meaning | C2: Data Type | D2: Student Use
A3: Record_ID | B3: Unique production record number | C3: Whole Number | D3: Record identification
A4: Production_Date | B4: Date of production activity | C4: Date | D4: Trend and monthly analysis
A5: Plant | B5: Manufacturing plant | C5: Category | D5: Plant comparison
A6: Production_Line | B6: Production line used | C6: Category | D6: Line performance
A7: Machine_ID | B7: Machine used for production | C7: Category | D7: Machine analysis
A8: Shift | B8: Production shift | C8: Category | D8: Shift comparison
A9: Product_Type | B9: Product manufactured | C9: Category | D9: Product analysis
A10: Batch_ID | B10: Unique production batch identifier | C10: Text | D10: Batch-level analysis
A11: Operator_ID | B11: Operator responsible for the batch | C11: Text | D11: Operator comparison
A12: Planned_Quantity | B12: Target production quantity | C12: Whole Number | D12: Target analysis
A13: Produced_Quantity | B13: Total units produced | C13: Whole Number | D13: Production analysis
... A50: Anomaly_Flag | B50: Threshold-based Normal / Warning / Critical | C50: Category | D50: Both

Sheet 03_Lookups
A1: LOOKUPS & THRESHOLDS
A3: Line 1 | B3: M101 | C3: Morning | D3: Product A | E3: No Downtime | G3: Labour_Cost_per_Hour | H3: 450/hr
A4: Line 2 | B4: M102 | C4: Evening | D4: Product B | E4: Machine Breakdown | G4: Energy_Cost_per_kWh | H4: 9
A5: Line 3 | B5: M103 | C5: Night | D5: Product C | E5: Material Shortage | G5: Currency | H5: INR
A6: Line 4 | B6: M201 | D6: Product D | E6: Power Failure
A7: Line 5 | B7: M202 | D7: Product E | E7: Tool Change
B8: M203 | E8: Preventive Maintenance
B9: M301 | E9: Quality Inspection
B10: M302 | E10: Operator Issue
B11: M303 | E11: Setup Time
A13: Risk / Anomaly Thresholds
A14: Threshold | B14: Value
A15: High downtime (min) | B15: 120
A16: Medium downtime (min) | B16: 60
A17: High temperature (°C) | B17: 85
A18: Warning temperature (°C) | B18: 80
A19: High vibration (mm/s) | B19: 4
A20: Warning vibration (mm/s) | B20: 3
A21: Critical defect rate | B21: 0.15
A22: Warning defect rate | B22: 0.08
A23: Critical OEE | B23: 0.75
A24: High OEE risk | B24: 0.8
A25: Warning OEE | B25: 0.85
A26: Maintenance delay (days) | B26: 30

Sheet 04_Calculations
A1: KPI CALCULATIONS & MANAGEMENT ANSWERS
A2: KPI | B2: Value
A3: Total Production | B3: =SUM('01_Manufacturing_Data'!L2:L1001) -> 692181
A4: Production Achievement % | B4: =AVERAGE('01_Manufacturing_Data'!AH2:AH1001) -> 0.93563915
A5: OEE % | B5: =AVERAGE('01_Manufacturing_Data'!AR2:AR1001) -> 0.87574039
A6: Defect Rate % | B6: =AVERAGE('01_Manufacturing_Data'!AI2:AI1001) -> 0.064913476
A7: Scrap Cost | B7: =SUM('01_Manufacturing_Data'!AD2:AD1001) -> 301043.7
A8: Downtime Hours | B8: =SUM('01_Manufacturing_Data'!AL2:AL1001) -> 420.95
A9: Revenue | B9: =SUM('01_Manufacturing_Data'!AA2:AA1001) -> 25038056
A10: Profit | B10: =SUM('01_Manufacturing_Data'!AG2:AG1001) -> 5088669.2
A13: BY PRODUCTION LINE
A14: Group | B14: Production | C14: Achievement % | D14: Downtime Hrs | E14: OEE % | F14: Defect Rate % | G14: Scrap Cost | H14: Profit
A15: Line 1 | B15: =SUMIF('01_Manufacturing_Data'!$E$2:$E$1001,$A15,'01_Manufacturing_Data'!$L$2:$L$1001) -> 154535 | C15: =AVERAGEIF('01_Manufacturing_Data'!$E$2:$E$1001,$A15,'01_Manufacturing_Data'!$AH$2:$AH$1001) -> 0.96891545 | D15: =SUMIF('01_Manufacturing_Data'!$E$2:$E$1001,$A15,'01_Manufacturing_Data'!$AL$2:$AL$1001) -> 77.833333 | E15: =AVERAGEIF('01_Manufacturing_Data'!$E$2:$E$1001,$A15,'01_Manufacturing_Data'!$AR$2:$AR$1001) -> 0.921476 | F15: =AVERAGEIF('01_Manufacturing_Data'!$E$2:$E$1001,$A15,'01_Manufacturing_Data'!$AI$2:$AI$1001) -> 0.049033038 | G15: =SUMIF('01_Manufacturing_Data'!$E$2:$E$1001,$A15,'01_Manufacturing_Data'!$AD$2:$AD$1001) -> 50339.315 | H15: =SUMIF('01_Manufacturing_Data'!$E$2:$E$1001,$A15,'01_Manufacturing_Data'!$AG$2:$AG$1001) -> 1226307.1
A16: Line 2 | B16: =SUMIF('01_Manufacturing_Data'!$E$2:$E$1001,$A16,'01_Manufacturing_Data'!$L$2:$L$1001) -> 140662 | C16: =AVERAGEIF('01_Manufacturing_Data'!$E$2:$E$1001,$A16,'01_Manufacturing_Data'!$AH$2:$AH$1001) -> 0.91144815 | D16: =SUMIF('01_Manufacturing_Data'!$E$2:$E$1001,$A16,'01_Manufacturing_Data'!$AL$2:$AL$1001) -> 94.633333 | E16: =AVERAGEIF('01_Manufacturing_Data'!$E$2:$E$1001,$A16,'01_Manufacturing_Data'!$AR$2:$AR$1001) -> 0.85199945 | F16: =AVERAGEIF('01_Manufacturing_Data'!$E$2:$E$1001,$A16,'01_Manufacturing_Data'!$AI$2:$AI$1001) -> 0.065437458 | G16: =SUMIF('01_Manufacturing_Data'!$E$2:$E$1001,$A16,'01_Manufacturing_Data'!$AD$2:$AD$1001) -> 62030.729 | H16: =SUMIF('01_Manufacturing_Data'!$E$2:$E$1001,$A16,'01_Manufacturing_Data'!$AG$2:$AG$1001) -> 1025441.9
A17: Line 3 | B17: =SUMIF('01_Manufacturing_Data'!$E$2:$E$1001,$A17,'01_Manufacturing_Data'!$L$2:$L$1001) -> 124166 | C17: =AVERAGEIF('01_Manufacturing_Data'!$E$2:$E$1001,$A17,'01_Manufacturing_Data'!$AH$2:$AH$1001) -> 0.87233305 | D17: =SUMIF('01_Manufacturing_Data'!$E$2:$E$1001,$A17,'01_Manufacturing_Data'!$AL$2:$AL$1001) -> 98.4 | E17: =AVERAGEIF('01_Manufacturing_Data'!$E$2:$E$1001,$A17,'01_Manufacturing_Data'!$AR$2:$AR$1001) -> 0.79090572 | F17: =AVERAGEIF('01_Manufacturing_Data'!$E$2:$E$1001,$A17,'01_Manufacturing_Data'!$AI$2:$AI$1001) -> 0.09373703 | G17: =SUMIF('01_Manufacturing_Data'!$E$2:$E$1001,$A17,'01_Manufacturing_Data'!$AD$2:$AD$1001) -> 78358.048 | H17: =SUMIF('01_Manufacturing_Data'!$E$2:$E$1001,$A17,'01_Manufacturing_Data'!$AG$2:$AG$1001) -> 760262.8
A18: Line 4 | B18: =SUMIF('01_Manufacturing_Data'!$E$2:$E$1001,$A18,'01_Manufacturing_Data'!$L$2:$L$1001) -> 141477 | C18: =AVERAGEIF('01_Manufacturing_Data'!$E$2:$E$1001,$A18,'01_Manufacturing_Data'!$AH$2:$AH$1001) -> 0.98792534 | D18: =SUMIF('01_Manufacturing_Data'!$E$2:$E$1001,$A18,'01_Manufacturing_Data'!$AL$2:$AL$1001) -> 65.85 | E18: =AVERAGEIF('01_Manufacturing_Data'!$E$2:$E$1001,$A18,'01_Manufacturing_Data'!$AR$2:$AR$1001) -> 0.93964448 | F18: =AVERAGEIF('01_Manufacturing_Data'!$E$2:$E$1001,$A18,'01_Manufacturing_Data'!$AI$2:$AI$1001) -> 0.04902233 | G18: =SUMIF('01_Manufacturing_Data'!$E$2:$E$1001,$A18,'01_Manufacturing_Data'!$AD$2:$AD$1001) -> 47228.223 | H18: =SUMIF('01_Manufacturing_Data'!$E$2:$E$1001,$A18,'01_Manufacturing_Data'!$AG$2:$AG$1001) -> 1156989.6
A19: Line 5 | B19: =SUMIF('01_Manufacturing_Data'!$E$2:$E$1001,$A19,'01_Manufacturing_Data'!$L$2:$L$1001) -> 131341 | C19: =AVERAGEIF('01_Manufacturing_Data'!$E$2:$E$1001,$A19,'01_Manufacturing_Data'!$AH$2:$AH$1001) -> 0.93417367 | D19: =SUMIF('01_Manufacturing_Data'!$E$2:$E$1001,$A19,'01_Manufacturing_Data'!$AL$2:$AL$1001) -> 84.233333 | E19: =AVERAGEIF('01_Manufacturing_Data'!$E$2:$E$1001,$A19,'01_Manufacturing_Data'!$AR$2:$AR$1001) -> 0.86901792 | F19: =AVERAGEIF('01_Manufacturing_Data'!$E$2:$E$1001,$A19,'01_Manufacturing_Data'!$AI$2:$AI$1001) -> 0.07011253 | G19: =SUMIF('01_Manufacturing_Data'!$E$2:$E$1001,$A19,'01_Manufacturing_Data'!$AD$2:$AD$1001) -> 63087.38 | H19: =SUMIF('01_Manufacturing_Data'!$E$2:$E$1001,$A19,'01_Manufacturing_Data'!$AG$2:$AG$1001) -> 919667.75
A23: BY MACHINE
A24: Group | B24: Production | C24: Downtime Hrs | D24: OEE % | E24: Defect Rate % | F24: Actual Cycle Sec | G24: Scrap | H24: Scrap Cost | I24: Maintenance Days | J24: Maintenance Risk High
A25: M101 | B25: =SUMIF('01_Manufacturing_Data'!$F$2:$F$1001,$A25,'01_Manufacturing_Data'!$L$2:$L$1001) -> 52753 | C25: =SUMIF('01_Manufacturing_Data'!$F$2:$F$1001,$A25,'01_Manufacturing_Data'!$AL$2:$AL$1001) -> 26.283333 | D25: =AVERAGEIF('01_Manufacturing_Data'!$F$2:$F$1001,$A25,'01_Manufacturing_Data'!$AR$2:$AR$1001) -> 0.9154095 | E25: =AVERAGEIF('01_Manufacturing_Data'!$F$2:$F$1001,$A25,'01_Manufacturing_Data'!$AI$2:$AI$1001) -> 0.039920091 | F25: =AVERAGEIF('01_Manufacturing_Data'!$F$2:$F$1001,$A25,'01_Manufacturing_Data'!$S$2:$S$1001) -> 52.066667 | G25: =SUMIF('01_Manufacturing_Data'!$F$2:$F$1001,$A25,'01_Manufacturing_Data'!$O$2:$O$1001) -> 609 | H25: =SUMIF('01_Manufacturing_Data'!$F$2:$F$1001,$A25,'01_Manufacturing_Data'!$AD$2:$AD$1001) -> 14050.164 | I25: =AVERAGEIF('01_Manufacturing_Data'!$F$2:$F$1001,$A25,'01_Manufacturing_Data'!$Z$2:$Z$1001) -> 23.24 | J25: =COUNTIFS('01_Manufacturing_Data'!$F$2:$F$1001,$A25,'01_Manufacturing_Data'!$AU$2:$AU$1001,"High") -> 14
A26: M102 | B26: =SUMIF('01_Manufacturing_Data'!$F$2:$F$1001,$A26,'01_Manufacturing_Data'!$L$2:$L$1001) -> 56403 | C26: =SUMIF('01_Manufacturing_Data'!$F$2:$F$1001,$A26,'01_Manufacturing_Data'!$AL$2:$AL$1001) -> 29.05 | D26: =AVERAGEIF('01_Manufacturing_Data'!$F$2:$F$1001,$A26,'01_Manufacturing_Data'!$AR$2:$AR$1001) -> 0.91167136 | E26: =AVERAGEIF('01_Manufacturing_Data'!$F$2:$F$1001,$A26,'01_Manufacturing_Data'!$AI$2:$AI$1001) -> 0.057823802 | F26: =AVERAGEIF('01_Manufacturing_Data'!$F$2:$F$1001,$A26,'01_Manufacturing_Data'!$S$2:$S$1001) -> 51.525641 | G26: =SUMIF('01_Manufacturing_Data'!$F$2:$F$1001,$A26,'01_Manufacturing_Data'!$O$2:$O$1001) -> 951 | H26: =SUMIF('01_Manufacturing_Data'!$F$2:$F$1001,$A26,'01_Manufacturing_Data'!$AD$2:$AD$1001) -> 21489.341 | I26: =AVERAGEIF('01_Manufacturing_Data'!$F$2:$F$1001,$A26,'01_Manufacturing_Data'!$Z$2:$Z$1001) -> 23.641026 | J26: =COUNTIFS('01_Manufacturing_Data'!$F$2:$F$1001,$A26,'01_Manufacturing_Data'!$AU$2:$AU$1001,"High") -> 17
A27: M103 | B27: =SUMIF('01_Manufacturing_Data'!$F$2:$F$1001,$A27,'01_Manufacturing_Data'!$L$2:$L$1001) -> 45379 | C27: =SUMIF('01_Manufacturing_Data'!$F$2:$F$1001,$A27,'01_Manufacturing_Data'!$AL$2:$AL$1001) -> 22.5 | D27: =AVERAGEIF('01_Manufacturing_Data'!$F$2:$F$1001,$A27,'01_Manufacturing_Data'!$AR$2:$AR$1001) -> 0.94083708 | E27: =AVERAGEIF('01_Manufacturing_Data'!$F$2:$F$1001,$A27,'01_Manufacturing_Data'!$AI$2:$AI$1001) -> 0.048997981 | F27: =AVERAGEIF('01_Manufacturing_Data'!$F$2:$F$1001,$A27,'01_Manufacturing_Data'!$S$2:$S$1001) -> 52.47619 | G27: =SUMIF('01_Manufacturing_Data'!$F$2:$F$1001,$A27,'01_Manufacturing_Data'!$O$2:$O$1001) -> 644 | H27: =SUMIF('01_Manufacturing_Data'!$F$2:$F$1001,$A27,'01_Manufacturing_Data'!$AD$2:$AD$1001) -> 14799.81 | I27: =AVERAGEIF('01_Manufacturing_Data'!$F$2:$F$1001,$A27,'01_Manufacturing_Data'!$Z$2:$Z$1001) -> 26.555556 | J27: =COUNTIFS('01_Manufacturing_Data'!$F$2:$F$1001,$A27,'01_Manufacturing_Data'!$AU$2:$AU$1001,"High") -> 13
A28: M201 | B28: =SUMIF('01_Manufacturing_Data'!$F$2:$F$1001,$A28,'01_Manufacturing_Data'!$L$2:$L$1001) -> 47334 | C28: =SUMIF('01_Manufacturing_Data'!$F$2:$F$1001,$A28,'01_Manufacturing_Data'!$AL$2:$AL$1001) -> 29.783333 | D28: =AVERAGEIF('01_Manufacturing_Data'!$F$2:$F$1001,$A28,'01_Manufacturing_Data'!$AR$2:$AR$1001) -> 0.84793916 | E28: =AVERAGEIF('01_Manufacturing_Data'!$F$2:$F$1001,$A28,'01_Manufacturing_Data'!$AI$2:$AI$1001) -> 0.067262191 | F28: =AVERAGEIF('01_Manufacturing_Data'!$F$2:$F$1001,$A28,'01_Manufacturing_Data'!$S$2:$S$1001) -> 50.771429 | G28: =SUMIF('01_Manufacturing_Data'!$F$2:$F$1001,$A28,'01_Manufacturing_Data'!$O$2:$O$1001) -> 952 | H28: =SUMIF('01_Manufacturing_Data'!$F$2:$F$1001,$A28,'01_Manufacturing_Data'!$AD$2:$AD$1001) -> 20770.637 | I28: =AVERAGEIF('01_Manufacturing_Data'!$F$2:$F$1001,$A28,'01_Manufacturing_Data'!$Z$2:$Z$1001) -> 26.357143 | J28: =COUNTIFS('01_Manufacturing_Data'!$F$2:$F$1001,$A28,'01_Manufacturing_Data'!$AU$2:$AU$1001,"High") -> 21
A29: M202 | B29: =SUMIF('01_Manufacturing_Data'!$F$2:$F$1001,$A29,'01_Manufacturing_Data'!$L$2:$L$1001) -> 46850 | C29: =SUMIF('01_Manufacturing_Data'!$F$2:$F$1001,$A29,'01_Manufacturing_Data'!$AL$2:$AL$1001) -> 28.183333 | D29: =AVERAGEIF('01_Manufacturing_Data'!$F$2:$F$1001,$A29,'01_Manufacturing_Data'!$AR$2:$AR$1001) -> 0.87788801 | E29: =AVERAGEIF('01_Manufacturing_Data'!$F$2:$F$1001,$A29,'01_Manufacturing_Data'!$AI$2:$AI$1001) -> 0.049584076 | F29: =AVERAGEIF('01_Manufacturing_Data'!$F$2:$F$1001,$A29,'01_Manufacturing_Data'!$S$2:$S$1001) -> 53.736111 | G29: =SUMIF('01_Manufacturing_Data'!$F$2:$F$1001,$A29,'01_Manufacturing_Data'!$O$2:$O$1001) -> 708 | H29: =SUMIF('01_Manufacturing_Data'!$F$2:$F$1001,$A29,'01_Manufacturing_Data'!$AD$2:$AD$1001) -> 16784.99 | I29: =AVERAGEIF('01_Manufacturing_Data'!$F$2:$F$1001,$A29,'01_Manufacturing_Data'!$Z$2:$Z$1001) -> 24.916667 | J29: =COUNTIFS('01_Manufacturing_Data'!$F$2:$F$1001,$A29,'01_Manufacturing_Data'!$AU$2:$AU$1001,"High") -> 22
A30: M203 | B30: =SUMIF('01_Manufacturing_Data'!$F$2:$F$1001,$A30,'01_Manufacturing_Data'!$L$2:$L$1001) -> 46478 | C30: =SUMIF('01_Manufacturing_Data'!$F$2:$F$1001,$A30,'01_Manufacturing_Data'!$AL$2:$AL$1001) -> 36.666667 | D30: =AVERAGEIF('01_Manufacturing_Data'!$F$2:$F$1001,$A30,'01_Manufacturing_Data'!$AR$2:$AR$1001) -> 0.82974936 | E30: =AVERAGEIF('01_Manufacturing_Data'!$F$2:$F$1001,$A30,'01_Manufacturing_Data'!$AI$2:$AI$1001) -> 0.079715094 | F30: =AVERAGEIF('01_Manufacturing_Data'!$F$2:$F$1001,$A30,'01_Manufacturing_Data'!$S$2:$S$1001) -> 53.478873 | G30: =SUMIF('01_Manufacturing_Data'!$F$2:$F$1001,$A30,'01_Manufacturing_Data'!$O$2:$O$1001) -> 1072 | H30: =SUMIF('01_Manufacturing_Data'!$F$2:$F$1001,$A30,'01_Manufacturing_Data'!$AD$2:$AD$1001) -> 24475.102 | I30: =AVERAGEIF('01_Manufacturing_Data'!$F$2:$F$1001,$A30,'01_Manufacturing_Data'!$Z$2:$Z$1001) -> 23.197183 | J30: =COUNTIFS('01_Manufacturing_Data'!$F$2:$F$1001,$A30,'01_Manufacturing_Data'!$AU$2:$AU$1001,"High") -> 28
A31: M301 | B31: =SUMIF('01_Manufacturing_Data'!$F$2:$F$1001,$A31,'01_Manufacturing_Data'!$L$2:$L$1001) -> 38328 | C31: =SUMIF('01_Manufacturing_Data'!$F$2:$F$1001,$A31,'01_Manufacturing_Data'!$AL$2:$AL$1001) -> 26.133333 | D31: =AVERAGEIF('01_Manufacturing_Data'!$F$2:$F$1001,$A31,'01_Manufacturing_Data'!$AR$2:$AR$1001) -> 0.81390045 | E31: =AVERAGEIF('01_Manufacturing_Data'!$F$2:$F$1001,$A31,'01_Manufacturing_Data'!$AI$2:$AI$1001) -> 0.08820497 | F31: =AVERAGEIF('01_Manufacturing_Data'!$F$2:$F$1001,$A31,'01_Manufacturing_Data'!$S$2:$S$1001) -> 52.810345 | G31: =SUMIF('01_Manufacturing_Data'!$F$2:$F$1001,$A31,'01_Manufacturing_Data'!$O$2:$O$1001) -> 1014 | H31: =SUMIF('01_Manufacturing_Data'!$F$2:$F$1001,$A31,'01_Manufacturing_Data'!$AD$2:$AD$1001) -> 23494.507 | I31: =AVERAGEIF('01_Manufacturing_Data'!$F$2:$F$1001,$A31,'01_Manufacturing_Data'!$Z$2:$Z$1001) -> 22.224138 | J31: =COUNTIFS('01_Manufacturing_Data'!$F$2:$F$1001,$A31,'01_Manufacturing_Data'!$AU$2:$AU$1001,"High") -> 27
A32: M302 | B32: =SUMIF('01_Manufacturing_Data'!$F$2:$F$1001,$A32,'01_Manufacturing_Data'!$L$2:$L$1001) -> 46212 | C32: =SUMIF('01_Manufacturing_Data'!$F$2:$F$1001,$A32,'01_Manufacturing_Data'!$AL$2:$AL$1001) -> 32.35 | D32: =AVERAGEIF('01_Manufacturing_Data'!$F$2:$F$1001,$A32,'01_Manufacturing_Data'!$AR$2:$AR$1001) -> 0.81692992 | E32: =AVERAGEIF('01_Manufacturing_Data'!$F$2:$F$1001,$A32,'01_Manufacturing_Data'!$AI$2:$AI$1001) -> 0.060029976 | F32: =AVERAGEIF('01_Manufacturing_Data'!$F$2:$F$1001,$A32,'01_Manufacturing_Data'!$S$2:$S$1001) -> 52.056338 | G32: =SUMIF('01_Manufacturing_Data'!$F$2:$F$1001,$A32,'01_Manufacturing_Data'!$O$2:$O$1001) -> 832 | H32: =SUMIF('01_Manufacturing_Data'!$F$2:$F$1001,$A32,'01_Manufacturing_Data'!$AD$2:$AD$1001) -> 19030.986 | I32: =AVERAGEIF('01_Manufacturing_Data'!$F$2:$F$1001,$A32,'01_Manufacturing_Data'!$Z$2:$Z$1001) -> 24.760563 | J32: =COUNTIFS('01_Manufacturing_Data'!$F$2:$F$1001,$A32,'01_Manufacturing_Data'!$AU$2:$AU$1001,"High") -> 34
A33: M303 | B33: =SUMIF('01_Manufacturing_Data'!$F$2:$F$1001,$A33,'01_Manufacturing_Data'!$L$2:$L$1001) -> 39626 | C33: =SUMIF('01_Manufacturing_Data'!$F$2:$F$1001,$A33,'01_Manufacturing_Data'!$AL$2:$AL$1001) -> 39.916667 | D33: =AVERAGEIF('01_Manufacturing_Data'!$F$2:$F$1001,$A33,'01_Manufacturing_Data'!$AR$2:$AR$1001) -> 0.73698348 | E33: =AVERAGEIF('01_Manufacturing_Data'!$F$2:$F$1001,$A33,'01_Manufacturing_Data'!$AI$2:$AI$1001) -> 0.13973805 | F33: =AVERAGEIF('01_Manufacturing_Data'!$F$2:$F$1001,$A33,'01_Manufacturing_Data'!$S$2:$S$1001) -> 53 | G33: =SUMIF('01_Manufacturing_Data'!$F$2:$F$1001,$A33,'01_Manufacturing_Data'!$O$2:$O$1001) -> 1639 | H33: =SUMIF('01_Manufacturing_Data'!$F$2:$F$1001,$A33,'01_Manufacturing_Data'!$AD$2:$AD$1001) -> 35832.555 | I33: =AVERAGEIF('01_Manufacturing_Data'!$F$2:$F$1001,$A33,'01_Manufacturing_Data'!$Z$2:$Z$1001) -> 41.186441 | J33: =COUNTIFS('01_Manufacturing_Data'!$F$2:$F$1001,$A33,'01_Manufacturing_Data'!$AU$2:$AU$1001,"High") -> 59
A34: M401 | B34: =SUMIF('01_Manufacturing_Data'!$F$2:$F$1001,$A34,'01_Manufacturing_Data'!$L$2:$L$1001) -> 43898 | C34: =SUMIF('01_Manufacturing_Data'!$F$2:$F$1001,$A34,'01_Manufacturing_Data'!$AL$2:$AL$1001) -> 17.016667 | D34: =AVERAGEIF('01_Manufacturing_Data'!$F$2:$F$1001,$A34,'01_Manufacturing_Data'!$AR$2:$AR$1001) -> 0.95947888 | E34: =AVERAGEIF('01_Manufacturing_Data'!$F$2:$F$1001,$A34,'01_Manufacturing_Data'!$AI$2:$AI$1001) -> 0.037558268 | F34: =AVERAGEIF('01_Manufacturing_Data'!$F$2:$F$1001,$A34,'01_Manufacturing_Data'!$S$2:$S$1001) -> 52.491525 | G34: =SUMIF('01_Manufacturing_Data'!$F$2:$F$1001,$A34,'01_Manufacturing_Data'!$O$2:$O$1001) -> 473 | H34: =SUMIF('01_Manufacturing_Data'!$F$2:$F$1001,$A34,'01_Manufacturing_Data'!$AD$2:$AD$1001) -> 10845.256 | I34: =AVERAGEIF('01_Manufacturing_Data'!$F$2:$F$1001,$A34,'01_Manufacturing_Data'!$Z$2:$Z$1001) -> 22 | J34: =COUNTIFS('01_Manufacturing_Data'!$F$2:$F$1001,$A34,'01_Manufacturing_Data'!$AU$2:$AU$1001,"High") -> 11
A35: M402 | B35: =SUMIF('01_Manufacturing_Data'!$F$2:$F$1001,$A35,'01_Manufacturing_Data'!$L$2:$L$1001) -> 44212 | C35: =SUMIF('01_Manufacturing_Data'!$F$2:$F$1001,$A35,'01_Manufacturing_Data'!$AL$2:$AL$1001) -> 22.866667 | D35: =AVERAGEIF('01_Manufacturing_Data'!$F$2:$F$1001,$A35,'01_Manufacturing_Data'!$AR$2:$AR$1001) -> 0.93916038 | E35: =AVERAGEIF('01_Manufacturing_Data'!$F$2:$F$1001,$A35,'01_Manufacturing_Data'!$AI$2:$AI$1001) -> 0.049168985 | F35: =AVERAGEIF('01_Manufacturing_Data'!$F$2:$F$1001,$A35,'01_Manufacturing_Data'!$S$2:$S$1001) -> 53.322581 | G35: =SUMIF('01_Manufacturing_Data'!$F$2:$F$1001,$A35,'01_Manufacturing_Data'!$O$2:$O$1001) -> 657 | H35: =SUMIF('01_Manufacturing_Data'!$F$2:$F$1001,$A35,'01_Manufacturing_Data'!$AD$2:$AD$1001) -> 15326.373 | I35: =AVERAGEIF('01_Manufacturing_Data'!$F$2:$F$1001,$A35,'01_Manufacturing_Data'!$Z$2:$Z$1001) -> 21.483871 | J35: =COUNTIFS('01_Manufacturing_Data'!$F$2:$F$1001,$A35,'01_Manufacturing_Data'!$AU$2:$AU$1001,"High") -> 13
A36: M403 | B36: =SUMIF('01_Manufacturing_Data'!$F$2:$F$1001,$A36,'01_Manufacturing_Data'!$L$2:$L$1001) -> 53367 | C36: =SUMIF('01_Manufacturing_Data'!$F$2:$F$1001,$A36,'01_Manufacturing_Data'!$AL$2:$AL$1001) -> 25.966667 | D36: =AVERAGEIF('01_Manufacturing_Data'!$F$2:$F$1001,$A36,'01_Manufacturing_Data'!$AR$2:$AR$1001) -> 0.92402508 | E36: =AVERAGEIF('01_Manufacturing_Data'!$F$2:$F$1001,$A36,'01_Manufacturing_Data'!$AI$2:$AI$1001) -> 0.058163247 | F36: =AVERAGEIF('01_Manufacturing_Data'!$F$2:$F$1001,$A36,'01_Manufacturing_Data'!$S$2:$S$1001) -> 51.643836 | G36: =SUMIF('01_Manufacturing_Data'!$F$2:$F$1001,$A36,'01_Manufacturing_Data'!$O$2:$O$1001) -> 928 | H36: =SUMIF('01_Manufacturing_Data'!$F$2:$F$1001,$A36,'01_Manufacturing_Data'!$AD$2:$AD$1001) -> 21056.594 | I36: =AVERAGEIF('01_Manufacturing_Data'!$F$2:$F$1001,$A36,'01_Manufacturing_Data'!$Z$2:$Z$1001) -> 22.767123 | J36: =COUNTIFS('01_Manufacturing_Data'!$F$2:$F$1001,$A36,'01_Manufacturing_Data'!$AU$2:$AU$1001,"High") -> 11
... A39: M503 | B39: =SUMIF('01_Manufacturing_Data'!$F$2:$F$1001,$A39,'01_Manufacturing_Data'!$L$2:$L$1001) -> 48361 | C39: =SUMIF('01_Manufacturing_Data'!$F$2:$F$1001,$A39,'01_Manufacturing_Data'!$AL$2:$AL$1001) -> 23.65 | D39: =AVERAGEIF('01_Manufacturing_Data'!$F$2:$F$1001,$A39,'01_Manufacturing_Data'!$AR$2:$AR$1001) -> 0.89922385 | E39: =AVERAGEIF('01_Manufacturing_Data'!$F$2:$F$1001,$A39,'01_Manufacturing_Data'!$AI$2:$AI$1001) -> 0.047027431 | F39: =AVERAGEIF('01_Manufacturing_Data'!$F$2:$F$1001,$A39,'01_Manufacturing_Data'!$S$2:$S$1001) -> 51.014706 | G39: =SUMIF('01_Manufacturing_Data'!$F$2:$F$1001,$A39,'01_Manufacturing_Data'!$O$2:$O$1001) -> 695 | H39: =SUMIF('01_Manufacturing_Data'!$F$2:$F$1001,$A39,'01_Manufacturing_Data'!$AD$2:$AD$1001) -> 15639.628 | I39: =AVERAGEIF('01_Manufacturing_Data'!$F$2:$F$1001,$A39,'01_Manufacturing_Data'!$Z$2:$Z$1001) -> 23.411765 | J39: =COUNTIFS('01_Manufacturing_Data'!$F$2:$F$1001,$A39,'01_Manufacturing_Data'!$AU$2:$AU$1001,"High") -> 18
A41: BY SHIFT
A42: Group | B42: Production | C42: Achievement % | D42: Downtime Hrs | E42: OEE % | F42: Defect Rate % | G42: Scrap Cost | H42: Profit
A43: Evening | B43: =SUMIF('01_Manufacturing_Data'!$G$2:$G$1001,$A43,'01_Manufacturing_Data'!$L$2:$L$1001) -> 258816 | C43: =AVERAGEIF('01_Manufacturing_Data'!$G$2:$G$1001,$A43,'01_Manufacturing_Data'!$AH$2:$AH$1001) -> 0.93269127 | D43: =SUMIF('01_Manufacturing_Data'!$G$2:$G$1001,$A43,'01_Manufacturing_Data'!$AL$2:$AL$1001) -> 155.51667 | E43: =AVERAGEIF('01_Manufacturing_Data'!$G$2:$G$1001,$A43,'01_Manufacturing_Data'!$AR$2:$AR$1001) -> 0.87416311 | F43: =AVERAGEIF('01_Manufacturing_Data'!$G$2:$G$1001,$A43,'01_Manufacturing_Data'!$AI$2:$AI$1001) -> 0.063336566 | G43: =SUMIF('01_Manufacturing_Data'!$G$2:$G$1001,$A43,'01_Manufacturing_Data'!$AD$2:$AD$1001) -> 108375.18 | H43: =SUMIF('01_Manufacturing_Data'!$G$2:$G$1001,$A43,'01_Manufacturing_Data'!$AG$2:$AG$1001) -> 1896715.4
A44: Morning | B44: =SUMIF('01_Manufacturing_Data'!$G$2:$G$1001,$A44,'01_Manufacturing_Data'!$L$2:$L$1001) -> 294044 | C44: =AVERAGEIF('01_Manufacturing_Data'!$G$2:$G$1001,$A44,'01_Manufacturing_Data'!$AH$2:$AH$1001) -> 0.98383417 | D44: =SUMIF('01_Manufacturing_Data'!$G$2:$G$1001,$A44,'01_Manufacturing_Data'!$AL$2:$AL$1001) -> 159.78333 | E44: =AVERAGEIF('01_Manufacturing_Data'!$G$2:$G$1001,$A44,'01_Manufacturing_Data'!$AR$2:$AR$1001) -> 0.9226178 | F44: =AVERAGEIF('01_Manufacturing_Data'!$G$2:$G$1001,$A44,'01_Manufacturing_Data'!$AI$2:$AI$1001) -> 0.062956409 | G44: =SUMIF('01_Manufacturing_Data'!$G$2:$G$1001,$A44,'01_Manufacturing_Data'!$AD$2:$AD$1001) -> 124177.78 | H44: =SUMIF('01_Manufacturing_Data'!$G$2:$G$1001,$A44,'01_Manufacturing_Data'!$AG$2:$AG$1001) -> 2215059.8
A45: Night | B45: =SUMIF('01_Manufacturing_Data'!$G$2:$G$1001,$A45,'01_Manufacturing_Data'!$L$2:$L$1001) -> 139321 | C45: =AVERAGEIF('01_Manufacturing_Data'!$G$2:$G$1001,$A45,'01_Manufacturing_Data'!$AH$2:$AH$1001) -> 0.85315492 | D45: =SUMIF('01_Manufacturing_Data'!$G$2:$G$1001,$A45,'01_Manufacturing_Data'!$AL$2:$AL$1001) -> 105.65 | E45: =AVERAGEIF('01_Manufacturing_Data'!$G$2:$G$1001,$A45,'01_Manufacturing_Data'!$AR$2:$AR$1001) -> 0.79338042 | F45: =AVERAGEIF('01_Manufacturing_Data'!$G$2:$G$1001,$A45,'01_Manufacturing_Data'!$AI$2:$AI$1001) -> 0.071065379 | G45: =SUMIF('01_Manufacturing_Data'!$G$2:$G$1001,$A45,'01_Manufacturing_Data'!$AD$2:$AD$1001) -> 68490.736 | H45: =SUMIF('01_Manufacturing_Data'!$G$2:$G$1001,$A45,'01_Manufacturing_Data'!$AG$2:$AG$1001) -> 976893.97
A48: BY PRODUCT
A49: Group | B49: Production | C49: Defect Rate % | D49: Scrap Rate % | E49: Scrap | F49: Scrap Cost | G49: Revenue | H49: Profit
A50: Product A | B50: =SUMIF('01_Manufacturing_Data'!$H$2:$H$1001,$A50,'01_Manufacturing_Data'!$L$2:$L$1001) -> 192748 | C50: =AVERAGEIF('01_Manufacturing_Data'!$H$2:$H$1001,$A50,'01_Manufacturing_Data'!$AI$2:$AI$1001) -> 0.063211363 | D50: =AVERAGEIF('01_Manufacturing_Data'!$H$2:$H$1001,$A50,'01_Manufacturing_Data'!$AJ$2:$AJ$1001) -> 0.018877206 | E50: =SUMIF('01_Manufacturing_Data'!$H$2:$H$1001,$A50,'01_Manufacturing_Data'!$O$2:$O$1001) -> 3595 | F50: =SUMIF('01_Manufacturing_Data'!$H$2:$H$1001,$A50,'01_Manufacturing_Data'!$AD$2:$AD$1001) -> 66572.844 | G50: =SUMIF('01_Manufacturing_Data'!$H$2:$H$1001,$A50,'01_Manufacturing_Data'!$AA$2:$AA$1001) -> 5774816.5 | H50: =SUMIF('01_Manufacturing_Data'!$H$2:$H$1001,$A50,'01_Manufacturing_Data'!$AG$2:$AG$1001) -> 1167679.6
...

Sheet 05_Student1_Operations
A1: STUDENT 1 — PRODUCTION & OPERATIONS
A2: Question | B2: Answer
A3: Highest production achievement line % | B3: Line - 4 (98.74)
A4: Machine with highest downtime | B4: M303 (39.9 hours)
A5: Best shift | B5: Morning (98.27%)
A6: Shift requiring investigation | B6: Night (85.30%)
A7: Lowest OEE machine | B7: M303 (73.70%)
A8: Top downtime reason | B8: Machine Breakdown (106.6hrs)
A9: Highest cycle-time machine | B9: M203 (53.48 secs)
B10: v
A11: Operational interpretation
A12: Line 4 has the highest average production achievement in the dataset.
A13: M303 has the highest total downtime and the lowest OEE; it warrants focused investigation.
A14: Morning has the highest average production achievement; Night has the lowest and should be investigated.
A15: Machine breakdown is the largest downtime category by total minutes.
A16: Cycle-time review should focus on machines whose actual cycle time is materially above the group average.
A19: Machine | B19: OEE % | C19: Downtime Hrs | D19: Actual Cycle Sec
A20: ='04_Calculations'!A25 -> M101 | B20: ='04_Calculations'!D25 -> 0.9154095 | C20: ='04_Calculations'!C25 -> 26.283333 | D20: ='04_Calculations'!E25 -> 0.039920091
A21: ='04_Calculations'!A26 -> M102 | B21: ='04_Calculations'!D26 -> 0.91167136 | C21: ='04_Calculations'!C26 -> 29.05 | D21: ='04_Calculations'!E26 -> 0.057823802
A22: ='04_Calculations'!A27 -> M103 | B22: ='04_Calculations'!D27 -> 0.94083708 | C22: ='04_Calculations'!C27 -> 22.5 | D22: ='04_Calculations'!E27 -> 0.048997981
A23: ='04_Calculations'!A28 -> M201 | B23: ='04_Calculations'!D28 -> 0.84793916 | C23: ='04_Calculations'!C28 -> 29.783333 | D23: ='04_Calculations'!E28 -> 0.067262191
A24: ='04_Calculations'!A29 -> M202 | B24: ='04_Calculations'!D29 -> 0.87788801 | C24: ='04_Calculations'!C29 -> 28.183333 | D24: ='04_Calculations'!E29 -> 0.049584076
A25: ='04_Calculations'!A30 -> M203 | B25: ='04_Calculations'!D30 -> 0.82974936 | C25: ='04_Calculations'!C30 -> 36.666667 | D25: ='04_Calculations'!E30 -> 0.079715094
A26: ='04_Calculations'!A31 -> M301 | B26: ='04_Calculations'!D31 -> 0.81390045 | C26: ='04_Calculations'!C31 -> 26.133333 | D26: ='04_Calculations'!E31 -> 0.08820497
A27: ='04_Calculations'!A32 -> M302 | B27: ='04_Calculations'!D32 -> 0.81692992 | C27: ='04_Calculations'!C32 -> 32.35 | D27: ='04_Calculations'!E32 -> 0.060029976
A28: ='04_Calculations'!A33 -> M303 | B28: ='04_Calculations'!D33 -> 0.73698348 | C28: ='04_Calculations'!C33 -> 39.916667 | D28: ='04_Calculations'!E33 -> 0.13973805
A29: ='04_Calculations'!A34 -> M401 | B29: ='04_Calculations'!D34 -> 0.95947888 | C29: ='04_Calculations'!C34 -> 17.016667 | D29: ='04_Calculations'!E34 -> 0.037558268
A30: ='04_Calculations'!A35 -> M402 | B30: ='04_Calculations'!D35 -> 0.93916038 | C30: ='04_Calculations'!C35 -> 22.866667 | D30: ='04_Calculations'!E35 -> 0.049168985
A31: ='04_Calculations'!A36 -> M403 | B31: ='04_Calculations'!D36 -> 0.92402508 | C31: ='04_Calculations'!C36 -> 25.966667 | D31: ='04_Calculations'!E36 -> 0.058163247
... A34: ='04_Calculations'!A39 -> M503 | B34: ='04_Calculations'!D39 -> 0.89922385 | C34: ='04_Calculations'!C39 -> 23.65 | D34: ='04_Calculations'!E39 -> 0.047027431

Sheet 06_Student2_Quality_Cost
A1: STUDENT 2 — QUALITY, COST & MAINTENANCE
A2: Question | B2: Answer
A3: Highest defect-rate product | B3: Product E
A4: Machine generating most scrap | B4: M303
A5: Shift with highest defect rate | B5: Night
A6: Total scrap cost | B6: 301043.7
A7: Highest-profit product | B7: Product A
A8: High maintenance-risk records | B8: 345 Records
A11: Quality & cost interpretation
A12: Product E has the highest average defect rate among the five products.
A13: M303 generates the largest scrap quantity and also has the highest total downtime.
A14: Night shift has the highest average defect rate.
A15: Total scrap cost is material and should be tracked by line, machine and product.
A16: Product A has the highest total profit, closely followed by Product B.
A17: Maintenance risk is rule-based; High is triggered by overdue maintenance or severe operating-condition thresholds.
A20: Product | B20: Defect Rate % | C20: Scrap Quantity | D20: Profit
A21: ='04_Calculations'!A50 -> Product A | B21: =AVERAGEIF('01_Manufacturing_Data'!$H$2:$H$1001,$A21,'01_Manufacturing_Data'!$AI$2:$AI$1001) -> 0.063211363 | C21: ='04_Calculations'!E50 -> 3595 | D21: ='04_Calculations'!G50 -> 5774816.5
A22: ='04_Calculations'!A51 -> Product B | B22: =AVERAGEIF('01_Manufacturing_Data'!$H$2:$H$1001,$A22,'01_Manufacturing_Data'!$AI$2:$AI$1001) -> 0.065182212 | C22: ='04_Calculations'!E51 -> 2984 | D22: ='04_Calculations'!G51 -> 5543057.5
A23: ='04_Calculations'!A52 -> Product C | B23: =AVERAGEIF('01_Manufacturing_Data'!$H$2:$H$1001,$A23,'01_Manufacturing_Data'!$AI$2:$AI$1001) -> 0.064527123 | C23: ='04_Calculations'!E52 -> 2130 | D23: ='04_Calculations'!G52 -> 4791216.5
A24: ='04_Calculations'!A53 -> Product D | B24: =AVERAGEIF('01_Manufacturing_Data'!$H$2:$H$1001,$A24,'01_Manufacturing_Data'!$AI$2:$AI$1001) -> 0.064731422 | C24: ='04_Calculations'!E53 -> 2902 | D24: ='04_Calculations'!G53 -> 4872236.7
A25: ='04_Calculations'!A54 -> Product E | B25: =AVERAGEIF('01_Manufacturing_Data'!$H$2:$H$1001,$A25,'01_Manufacturing_Data'!$AI$2:$AI$1001) -> 0.067868299 | C25: ='04_Calculations'!E54 -> 1641 | D25: ='04_Calculations'!G54 -> 4056728.5

Sheet 07_AI_Usage_Log
A1: AI USAGE LOG
A2: Date | B2: AI Tool | C2: Prompt | D2: Purpose | E2: AI Output Summary | F2: Excel Validation | G2: Final Decision
A3: 46284 | B3: ChatGPT | C3: Review manufacturing columns and suggest data-validation, calculated KPI and anomaly logic. | D3: Data cleaning & formula creation | E3: Suggested checks for IDs, quantities, downtime, cycle time, quality, maintenance and derived KPIs. | F3: Validated against 1,000-row dataset and Excel formulas. | G3: Use formulas and rule-based flags; verify all outputs in Excel.
A4: 46284 | B4: ChatGPT | C4: Suggest formulas for production achievement, defect rate, scrap rate, good rate, downtime hours, performance, quality, OEE and unit economics. | D4: Formula creation | E4: Provided row-level formulas using source columns. | F4: Formulas placed in 01_Manufacturing_Data and recalculated in spreadsheet. | G4: Use formula-driven KPIs.
A5: 46284 | B5: ChatGPT | C5: Interpret unusual downtime, cycle time, temperature, vibration, defects and OEE patterns. | D5: Anomaly investigation | E5: Highlighted machines and shifts requiring investigation based on thresholds and aggregated results. | F5: Validated through Excel-style aggregate calculations. | G5: Use Maintenance_Risk and Anomaly_Flag for investigation.
A6: 46284 | B6: ChatGPT | C6: Draft management insights from calculated findings. | D6: Management insights | E6: Generated concise findings tied to production, downtime, quality, cost and profit. | F6: Checked against the calculated summary tables. | G6: Keep only dataset-supported statements.

Sheet 08_Management_Dashboard
A1: MANUFACTURING MANAGEMENT DASHBOARD
D3: Achievement % | G3: OEE % | J3: Defect Rate %
A4: ='04_Calculations'!B3 -> 692181 | D4: ='04_Calculations'!B4 -> 0.93563915 | G4: ='04_Calculations'!B5 -> 0.87574039 | J4: ='04_Calculations'!B6 -> 0.064913476
A7: Scrap Cost | D7: Downtime Hours | G7: Revenue | J7: Profit
A8: ='04_Calculations'!B7 -> 301043.7 | D8: ='04_Calculations'!B8 -> 420.95 | G8: ='04_Calculations'!B9 -> 25038056 | J8: ='04_Calculations'!B10 -> 5088669.2
A13: Line | B13: OEE % | D13: Machine | E13: Downtime Hrs | G13: Product | H13: Defect Rate % | J13: Month | K13: Production
A14: ='04_Calculations'!A15 -> Line 1 | B14: ='04_Calculations'!E15 -> 0.921476 | D14: ='04_Calculations'!A25 -> M101 | E14: ='04_Calculations'!C25 -> 26.283333 | G14: ='04_Calculations'!A50 -> Product A | H14: ='04_Calculations'!C50 -> 0.063211363 | J14: ='04_Calculations'!A71 -> 2026-01 | K14: ='04_Calculations'!B71 -> 123582
A15: ='04_Calculations'!A16 -> Line 2 | B15: ='04_Calculations'!E16 -> 0.85199945 | D15: ='04_Calculations'!A26 -> M102 | E15: ='04_Calculations'!C26 -> 29.05 | G15: ='04_Calculations'!A51 -> Product B | H15: ='04_Calculations'!C51 -> 0.065182212 | J15: ='04_Calculations'!A72 -> 2026-02 | K15: ='04_Calculations'!B72 -> 108462
A16: ='04_Calculations'!A17 -> Line 3 | B16: ='04_Calculations'!E17 -> 0.79090572 | D16: ='04_Calculations'!A27 -> M103 | E16: ='04_Calculations'!C27 -> 22.5 | G16: ='04_Calculations'!A52 -> Product C | H16: ='04_Calculations'!C52 -> 0.064527123 | J16: ='04_Calculations'!A73 -> 2026-03 | K16: ='04_Calculations'!B73 -> 110123
A17: ='04_Calculations'!A18 -> Line 4 | B17: ='04_Calculations'!E18 -> 0.93964448 | D17: ='04_Calculations'!A28 -> M201 | E17: ='04_Calculations'!C28 -> 29.783333 | G17: ='04_Calculations'!A53 -> Product D | H17: ='04_Calculations'!C53 -> 0.064731422 | J17: ='04_Calculations'!A74 -> 2026-04 | K17: ='04_Calculations'!B74 -> 116277
A18: ='04_Calculations'!A19 -> Line 5 | B18: ='04_Calculations'!E19 -> 0.86901792 | D18: ='04_Calculations'!A29 -> M202 | E18: ='04_Calculations'!C29 -> 28.183333 | G18: ='04_Calculations'!A54 -> Product E | H18: ='04_Calculations'!C54 -> 0.067868299 | J18: ='04_Calculations'!A75 -> 2026-05 | K18: ='04_Calculations'!B75 -> 116924
D19: ='04_Calculations'!A30 -> M203 | E19: ='04_Calculations'!C30 -> 36.666667 | J19: ='04_Calculations'!A76 -> 2026-06 | K19: ='04_Calculations'!B76 -> 116813
D20: ='04_Calculations'!A31 -> M301 | E20: ='04_Calculations'!C31 -> 26.133333
D21: ='04_Calculations'!A32 -> M302 | E21: ='04_Calculations'!C32 -> 32.35
D22: ='04_Calculations'!A33 -> M303 | E22: ='04_Calculations'!C33 -> 39.916667
D23: ='04_Calculations'!A34 -> M401 | E23: ='04_Calculations'!C34 -> 17.016667
D24: ='04_Calculations'!A35 -> M402 | E24: ='04_Calculations'!C35 -> 22.866667
D25: ='04_Calculations'!A36 -> M403 | E25: ='04_Calculations'!C36 -> 25.966667
D26: ='04_Calculations'!A37 -> M501 | E26: ='04_Calculations'!C37 -> 26.533333
D27: ='04_Calculations'!A38 -> M502 | E27: ='04_Calculations'!C38 -> 34.05
D28: ='04_Calculations'!A39 -> M503 | E28: ='04_Calculations'!C39 -> 23.65
A73: TOP 5 EVIDENCE-BASED MANAGEMENT RECOMMENDATIONS
A74: 1. Investigate M303 first: it has the highest downtime, lowest OEE, highest defect rate and highest scrap quantity among machines.
A75: 2. Reduce machine-breakdown downtime: it is the largest downtime reason by total minutes.
A76: 3. Investigate Night shift performance: it has the lowest production achievement and highest defect rate.
A77: 4. Focus quality improvement on Product E: it has the highest average defect rate.
A78: 5. Strengthen preventive maintenance follow-up for overdue/pending risk cases and review temperature/vibration outliers.
